Traceback (most recent call last):
  File "/Users/hyacinthampadu/miniforge3/envs/py36/lib/python3.8/site-packages/pandas/core/indexes/base.py", line 3621, in get_loc
    return self._engine.get_loc(casted_key)
  File "pandas/_libs/index.pyx", line 136, in pandas._libs.index.IndexEngine.get_loc
  File "pandas/_libs/index.pyx", line 163, in pandas._libs.index.IndexEngine.get_loc
  File "pandas/_libs/hashtable_class_helper.pxi", line 5198, in pandas._libs.hashtable.PyObjectHashTable.get_item
  File "pandas/_libs/hashtable_class_helper.pxi", line 5206, in pandas._libs.hashtable.PyObjectHashTable.get_item
KeyError: 'converted'
The above exception was the direct cause of the following exception:
Traceback (most recent call last):
  File "experiment_tracking.py", line 46, in <module>
    main(name, model)
  File "experiment_tracking.py", line 20, in main
    X_res,y_res = process_data(df)
  File "/Users/hyacinthampadu/Documents/Jos Folder/Data Science/Portfolio/lead_converision/data_preprocess.py", line 15, in process_data
    df['converted']=pd.Series(np.where(df['converted'].values == 0, 0, 1),df.index)
  File "/Users/hyacinthampadu/miniforge3/envs/py36/lib/python3.8/site-packages/pandas/core/frame.py", line 3505, in __getitem__
    indexer = self.columns.get_loc(key)
  File "/Users/hyacinthampadu/miniforge3/envs/py36/lib/python3.8/site-packages/pandas/core/indexes/base.py", line 3623, in get_loc
    raise KeyError(key) from err
KeyError: 'converted'